Workbook

Sheet Cálculo
A1: Financiamento: Price × SAC
A2: Preencha apenas as células amarelas. O resto é calculado.
A3: Fonte: Tabela Price e SAC, juros compostos mensais sobre o saldo devedor
A4: Estimativa para fins informativos; não é aconselhamento jurídico ou financeiro. Confira a fonte oficial e a convenção coletiva da sua categoria.
A6: Valor financiado | B6: 100000
A7: Taxa de juros mensal (%) | B7: 1
A8: Prazo (meses, até 360) | B8: 12
A10: Price: parcela fixa | B10: =IF(B7=0,B6/B8,B6*(B7/100)/(1-(1+B7/100)^(-B8))) -> 8884.8789
A11: Price: total pago | B11: =B10*B8 -> 106618.55
A12: Price: juros totais | B12: =B11-B6 -> 6618.5464
A13: SAC: primeira parcela | B13: =B6/B8+B6*B7/100 -> 9333.3333
A14: SAC: última parcela | B14: =B6/B8+(B6/B8)*B7/100 -> 8416.6667
A15: SAC: total pago | B15: =B6+B6*(B7/100)*(B8+1)/2 -> 106500
A16: SAC: juros totais | B16: =B15-B6 -> 6500
A17: Diferença de juros (Price − SAC) | B17: =B12-B16 -> 118.54641 | C17: Sem IOF, seguros e tarifas

Sheet Parcelas
A1: Mês | B1: Saldo SAC | C1: Parcela SAC | D1: Saldo Price | E1: Parcela Price
A2: =IF(1<=Cálculo!$B$8,1,"") -> 1 | B2: =IF(A2="","",Cálculo!$B$6) -> 100000 | C2: =IF(A2="","",Cálculo!$B$6/Cálculo!$B$8+B2*Cálculo!$B$7/100) -> 9333.3333 | D2: =IF(A2="","",Cálculo!$B$6) -> 100000 | E2: =IF(A2="","",Cálculo!$B$10) -> 8884.8789
A3: =IF(2<=Cálculo!$B$8,2,"") -> 2 | B3: =IF(A3="","",B2-Cálculo!$B$6/Cálculo!$B$8) -> 91666.667 | C3: =IF(A3="","",Cálculo!$B$6/Cálculo!$B$8+B3*Cálculo!$B$7/100) -> 9250 | D3: =IF(A3="","",D2-(Cálculo!$B$10-D2*Cálculo!$B$7/100)) -> 92115.121 | E3: =IF(A3="","",Cálculo!$B$10) -> 8884.8789
A4: =IF(3<=Cálculo!$B$8,3,"") -> 3 | B4: =IF(A4="","",B3-Cálculo!$B$6/Cálculo!$B$8) -> 83333.333 | C4: =IF(A4="","",Cálculo!$B$6/Cálculo!$B$8+B4*Cálculo!$B$7/100) -> 9166.6667 | D4: =IF(A4="","",D3-(Cálculo!$B$10-D3*Cálculo!$B$7/100)) -> 84151.393 | E4: =IF(A4="","",Cálculo!$B$10) -> 8884.8789
A5: =IF(4<=Cálculo!$B$8,4,"") -> 4 | B5: =IF(A5="","",B4-Cálculo!$B$6/Cálculo!$B$8) -> 75000 | C5: =IF(A5="","",Cálculo!$B$6/Cálculo!$B$8+B5*Cálculo!$B$7/100) -> 9083.3333 | D5: =IF(A5="","",D4-(Cálculo!$B$10-D4*Cálculo!$B$7/100)) -> 76108.029 | E5: =IF(A5="","",Cálculo!$B$10) -> 8884.8789
A6: =IF(5<=Cálculo!$B$8,5,"") -> 5 | B6: =IF(A6="","",B5-Cálculo!$B$6/Cálculo!$B$8) -> 66666.667 | C6: =IF(A6="","",Cálculo!$B$6/Cálculo!$B$8+B6*Cálculo!$B$7/100) -> 9000 | D6: =IF(A6="","",D5-(Cálculo!$B$10-D5*Cálculo!$B$7/100)) -> 67984.23 | E6: =IF(A6="","",Cálculo!$B$10) -> 8884.8789
A7: =IF(6<=Cálculo!$B$8,6,"") -> 6 | B7: =IF(A7="","",B6-Cálculo!$B$6/Cálculo!$B$8) -> 58333.333 | C7: =IF(A7="","",Cálculo!$B$6/Cálculo!$B$8+B7*Cálculo!$B$7/100) -> 8916.6667 | D7: =IF(A7="","",D6-(Cálculo!$B$10-D6*Cálculo!$B$7/100)) -> 59779.193 | E7: =IF(A7="","",Cálculo!$B$10) -> 8884.8789
A8: =IF(7<=Cálculo!$B$8,7,"") -> 7 | B8: =IF(A8="","",B7-Cálculo!$B$6/Cálculo!$B$8) -> 50000 | C8: =IF(A8="","",Cálculo!$B$6/Cálculo!$B$8+B8*Cálculo!$B$7/100) -> 8833.3333 | D8: =IF(A8="","",D7-(Cálculo!$B$10-D7*Cálculo!$B$7/100)) -> 51492.106 | E8: =IF(A8="","",Cálculo!$B$10) -> 8884.8789
A9: =IF(8<=Cálculo!$B$8,8,"") -> 8 | B9: =IF(A9="","",B8-Cálculo!$B$6/Cálculo!$B$8) -> 41666.667 | C9: =IF(A9="","",Cálculo!$B$6/Cálculo!$B$8+B9*Cálculo!$B$7/100) -> 8750 | D9: =IF(A9="","",D8-(Cálculo!$B$10-D8*Cálculo!$B$7/100)) -> 43122.149 | E9: =IF(A9="","",Cálculo!$B$10) -> 8884.8789
A10: =IF(9<=Cálculo!$B$8,9,"") -> 9 | B10: =IF(A10="","",B9-Cálculo!$B$6/Cálculo!$B$8) -> 33333.333 | C10: =IF(A10="","",Cálculo!$B$6/Cálculo!$B$8+B10*Cálculo!$B$7/100) -> 8666.6667 | D10: =IF(A10="","",D9-(Cálculo!$B$10-D9*Cálculo!$B$7/100)) -> 34668.491 | E10: =IF(A10="","",Cálculo!$B$10) -> 8884.8789
A11: =IF(10<=Cálculo!$B$8,10,"") -> 10 | B11: =IF(A11="","",B10-Cálculo!$B$6/Cálculo!$B$8) -> 25000 | C11: =IF(A11="","",Cálculo!$B$6/Cálculo!$B$8+B11*Cálculo!$B$7/100) -> 8583.3333 | D11: =IF(A11="","",D10-(Cálculo!$B$10-D10*Cálculo!$B$7/100)) -> 26130.297 | E11: =IF(A11="","",Cálculo!$B$10) -> 8884.8789
A12: =IF(11<=Cálculo!$B$8,11,"") -> 11 | B12: =IF(A12="","",B11-Cálculo!$B$6/Cálculo!$B$8) -> 16666.667 | C12: =IF(A12="","",Cálculo!$B$6/Cálculo!$B$8+B12*Cálculo!$B$7/100) -> 8500 | D12: =IF(A12="","",D11-(Cálculo!$B$10-D11*Cálculo!$B$7/100)) -> 17506.721 | E12: =IF(A12="","",Cálculo!$B$10) -> 8884.8789
A13: =IF(12<=Cálculo!$B$8,12,"") -> 12 | B13: =IF(A13="","",B12-Cálculo!$B$6/Cálculo!$B$8) -> 8333.3333 | C13: =IF(A13="","",Cálculo!$B$6/Cálculo!$B$8+B13*Cálculo!$B$7/100) -> 8416.6667 | D13: =IF(A13="","",D12-(Cálculo!$B$10-D12*Cálculo!$B$7/100)) -> 8796.9098 | E13: =IF(A13="","",Cálculo!$B$10) -> 8884.8789
A14: =IF(13<=Cálculo!$B$8,13,"") | B14: =IF(A14="","",B13-Cálculo!$B$6/Cálculo!$B$8) | C14: =IF(A14="","",Cálculo!$B$6/Cálculo!$B$8+B14*Cálculo!$B$7/100) | D14: =IF(A14="","",D13-(Cálculo!$B$10-D13*Cálculo!$B$7/100)) | E14: =IF(A14="","",Cálculo!$B$10)
A15: =IF(14<=Cálculo!$B$8,14,"") | B15: =IF(A15="","",B14-Cálculo!$B$6/Cálculo!$B$8) | C15: =IF(A15="","",Cálculo!$B$6/Cálculo!$B$8+B15*Cálculo!$B$7/100) | D15: =IF(A15="","",D14-(Cálculo!$B$10-D14*Cálculo!$B$7/100)) | E15: =IF(A15="","",Cálculo!$B$10)
A16: =IF(15<=Cálculo!$B$8,15,"") | B16: =IF(A16="","",B15-Cálculo!$B$6/Cálculo!$B$8) | C16: =IF(A16="","",Cálculo!$B$6/Cálculo!$B$8+B16*Cálculo!$B$7/100) | D16: =IF(A16="","",D15-(Cálculo!$B$10-D15*Cálculo!$B$7/100)) | E16: =IF(A16="","",Cálculo!$B$10)
A17: =IF(16<=Cálculo!$B$8,16,"") | B17: =IF(A17="","",B16-Cálculo!$B$6/Cálculo!$B$8) | C17: =IF(A17="","",Cálculo!$B$6/Cálculo!$B$8+B17*Cálculo!$B$7/100) | D17: =IF(A17="","",D16-(Cálculo!$B$10-D16*Cálculo!$B$7/100)) | E17: =IF(A17="","",Cálculo!$B$10)
A18: =IF(17<=Cálculo!$B$8,17,"") | B18: =IF(A18="","",B17-Cálculo!$B$6/Cálculo!$B$8) | C18: =IF(A18="","",Cálculo!$B$6/Cálculo!$B$8+B18*Cálculo!$B$7/100) | D18: =IF(A18="","",D17-(Cálculo!$B$10-D17*Cálculo!$B$7/100)) | E18: =IF(A18="","",Cálculo!$B$10)
A19: =IF(18<=Cálculo!$B$8,18,"") | B19: =IF(A19="","",B18-Cálculo!$B$6/Cálculo!$B$8) | C19: =IF(A19="","",Cálculo!$B$6/Cálculo!$B$8+B19*Cálculo!$B$7/100) | D19: =IF(A19="","",D18-(Cálculo!$B$10-D18*Cálculo!$B$7/100)) | E19: =IF(A19="","",Cálculo!$B$10)
A20: =IF(19<=Cálculo!$B$8,19,"") | B20: =IF(A20="","",B19-Cálculo!$B$6/Cálculo!$B$8) | C20: =IF(A20="","",Cálculo!$B$6/Cálculo!$B$8+B20*Cálculo!$B$7/100) | D20: =IF(A20="","",D19-(Cálculo!$B$10-D19*Cálculo!$B$7/100)) | E20: =IF(A20="","",Cálculo!$B$10)
A21: =IF(20<=Cálculo!$B$8,20,"") | B21: =IF(A21="","",B20-Cálculo!$B$6/Cálculo!$B$8) | C21: =IF(A21="","",Cálculo!$B$6/Cálculo!$B$8+B21*Cálculo!$B$7/100) | D21: =IF(A21="","",D20-(Cálculo!$B$10-D20*Cálculo!$B$7/100)) | E21: =IF(A21="","",Cálculo!$B$10)
A22: =IF(21<=Cálculo!$B$8,21,"") | B22: =IF(A22="","",B21-Cálculo!$B$6/Cálculo!$B$8) | C22: =IF(A22="","",Cálculo!$B$6/Cálculo!$B$8+B22*Cálculo!$B$7/100) | D22: =IF(A22="","",D21-(Cálculo!$B$10-D21*Cálculo!$B$7/100)) | E22: =IF(A22="","",Cálculo!$B$10)
A23: =IF(22<=Cálculo!$B$8,22,"") | B23: =IF(A23="","",B22-Cálculo!$B$6/Cálculo!$B$8) | C23: =IF(A23="","",Cálculo!$B$6/Cálculo!$B$8+B23*Cálculo!$B$7/100) | D23: =IF(A23="","",D22-(Cálculo!$B$10-D22*Cálculo!$B$7/100)) | E23: =IF(A23="","",Cálculo!$B$10)
A24: =IF(23<=Cálculo!$B$8,23,"") | B24: =IF(A24="","",B23-Cálculo!$B$6/Cálculo!$B$8) | C24: =IF(A24="","",Cálculo!$B$6/Cálculo!$B$8+B24*Cálculo!$B$7/100) | D24: =IF(A24="","",D23-(Cálculo!$B$10-D23*Cálculo!$B$7/100)) | E24: =IF(A24="","",Cálculo!$B$10)
A25: =IF(24<=Cálculo!$B$8,24,"") | B25: =IF(A25="","",B24-Cálculo!$B$6/Cálculo!$B$8) | C25: =IF(A25="","",Cálculo!$B$6/Cálculo!$B$8+B25*Cálculo!$B$7/100) | D25: =IF(A25="","",D24-(Cálculo!$B$10-D24*Cálculo!$B$7/100)) | E25: =IF(A25="","",Cálculo!$B$10)
A26: =IF(25<=Cálculo!$B$8,25,"") | B26: =IF(A26="","",B25-Cálculo!$B$6/Cálculo!$B$8) | C26: =IF(A26="","",Cálculo!$B$6/Cálculo!$B$8+B26*Cálculo!$B$7/100) | D26: =IF(A26="","",D25-(Cálculo!$B$10-D25*Cálculo!$B$7/100)) | E26: =IF(A26="","",Cálculo!$B$10)
A27: =IF(26<=Cálculo!$B$8,26,"") | B27: =IF(A27="","",B26-Cálculo!$B$6/Cálculo!$B$8) | C27: =IF(A27="","",Cálculo!$B$6/Cálculo!$B$8+B27*Cálculo!$B$7/100) | D27: =IF(A27="","",D26-(Cálculo!$B$10-D26*Cálculo!$B$7/100)) | E27: =IF(A27="","",Cálculo!$B$10)
A28: =IF(27<=Cálculo!$B$8,27,"") | B28: =IF(A28="","",B27-Cálculo!$B$6/Cálculo!$B$8) | C28: =IF(A28="","",Cálculo!$B$6/Cálculo!$B$8+B28*Cálculo!$B$7/100) | D28: =IF(A28="","",D27-(Cálculo!$B$10-D27*Cálculo!$B$7/100)) | E28: =IF(A28="","",Cálculo!$B$10)
A29: =IF(28<=Cálculo!$B$8,28,"") | B29: =IF(A29="","",B28-Cálculo!$B$6/Cálculo!$B$8) | C29: =IF(A29="","",Cálculo!$B$6/Cálculo!$B$8+B29*Cálculo!$B$7/100) | D29: =IF(A29="","",D28-(Cálculo!$B$10-D28*Cálculo!$B$7/100)) | E29: =IF(A29="","",Cálculo!$B$10)
A30: =IF(29<=Cálculo!$B$8,29,"") | B30: =IF(A30="","",B29-Cálculo!$B$6/Cálculo!$B$8) | C30: =IF(A30="","",Cálculo!$B$6/Cálculo!$B$8+B30*Cálculo!$B$7/100) | D30: =IF(A30="","",D29-(Cálculo!$B$10-D29*Cálculo!$B$7/100)) | E30: =IF(A30="","",Cálculo!$B$10)
A31: =IF(30<=Cálculo!$B$8,30,"") | B31: =IF(A31="","",B30-Cálculo!$B$6/Cálculo!$B$8) | C31: =IF(A31="","",Cálculo!$B$6/Cálculo!$B$8+B31*Cálculo!$B$7/100) | D31: =IF(A31="","",D30-(Cálculo!$B$10-D30*Cálculo!$B$7/100)) | E31: =IF(A31="","",Cálculo!$B$10)
A32: =IF(31<=Cálculo!$B$8,31,"") | B32: =IF(A32="","",B31-Cálculo!$B$6/Cálculo!$B$8) | C32: =IF(A32="","",Cálculo!$B$6/Cálculo!$B$8+B32*Cálculo!$B$7/100) | D32: =IF(A32="","",D31-(Cálculo!$B$10-D31*Cálculo!$B$7/100)) | E32: =IF(A32="","",Cálculo!$B$10)
A33: =IF(32<=Cálculo!$B$8,32,"") | B33: =IF(A33="","",B32-Cálculo!$B$6/Cálculo!$B$8) | C33: =IF(A33="","",Cálculo!$B$6/Cálculo!$B$8+B33*Cálculo!$B$7/100) | D33: =IF(A33="","",D32-(Cálculo!$B$10-D32*Cálculo!$B$7/100)) | E33: =IF(A33="","",Cálculo!$B$10)
A34: =IF(33<=Cálculo!$B$8,33,"") | B34: =IF(A34="","",B33-Cálculo!$B$6/Cálculo!$B$8) | C34: =IF(A34="","",Cálculo!$B$6/Cálculo!$B$8+B34*Cálculo!$B$7/100) | D34: =IF(A34="","",D33-(Cálculo!$B$10-D33*Cálculo!$B$7/100)) | E34: =IF(A34="","",Cálculo!$B$10)
A35: =IF(34<=Cálculo!$B$8,34,"") | B35: =IF(A35="","",B34-Cálculo!$B$6/Cálculo!$B$8) | C35: =IF(A35="","",Cálculo!$B$6/Cálculo!$B$8+B35*Cálculo!$B$7/100) | D35: =IF(A35="","",D34-(Cálculo!$B$10-D34*Cálculo!$B$7/100)) | E35: =IF(A35="","",Cálculo!$B$10)
A36: =IF(35<=Cálculo!$B$8,35,"") | B36: =IF(A36="","",B35-Cálculo!$B$6/Cálculo!$B$8) | C36: =IF(A36="","",Cálculo!$B$6/Cálculo!$B$8+B36*Cálculo!$B$7/100) | D36: =IF(A36="","",D35-(Cálculo!$B$10-D35*Cálculo!$B$7/100)) | E36: =IF(A36="","",Cálculo!$B$10)
A37: =IF(36<=Cálculo!$B$8,36,"") | B37: =IF(A37="","",B36-Cálculo!$B$6/Cálculo!$B$8) | C37: =IF(A37="","",Cálculo!$B$6/Cálculo!$B$8+B37*Cálculo!$B$7/100) | D37: =IF(A37="","",D36-(Cálculo!$B$10-D36*Cálculo!$B$7/100)) | E37: =IF(A37="","",Cálculo!$B$10)
A38: =IF(37<=Cálculo!$B$8,37,"") | B38: =IF(A38="","",B37-Cálculo!$B$6/Cálculo!$B$8) | C38: =IF(A38="","",Cálculo!$B$6/Cálculo!$B$8+B38*Cálculo!$B$7/100) | D38: =IF(A38="","",D37-(Cálculo!$B$10-D37*Cálculo!$B$7/100)) | E38: =IF(A38="","",Cálculo!$B$10)
A39: =IF(38<=Cálculo!$B$8,38,"") | B39: =IF(A39="","",B38-Cálculo!$B$6/Cálculo!$B$8) | C39: =IF(A39="","",Cálculo!$B$6/Cálculo!$B$8+B39*Cálculo!$B$7/100) | D39: =IF(A39="","",D38-(Cálculo!$B$10-D38*Cálculo!$B$7/100)) | E39: =IF(A39="","",Cálculo!$B$10)
A40: =IF(39<=Cálculo!$B$8,39,"") | B40: =IF(A40="","",B39-Cálculo!$B$6/Cálculo!$B$8) | C40: =IF(A40="","",Cálculo!$B$6/Cálculo!$B$8+B40*Cálculo!$B$7/100) | D40: =IF(A40="","",D39-(Cálculo!$B$10-D39*Cálculo!$B$7/100)) | E40: =IF(A40="","",Cálculo!$B$10)
...
